Workbook

Sheet Dynamic Dashboard
A1: DYNAMIC CORE MENTORS DASHBOARD
A2: Auto-Updates When Source Data Changes | VSM | PSP | TPI
A3: Last Updated: | B3: =TODAY() -> 45945
A5: 📊 CORE MENTORS DATA (AUTO-UPDATING)
A7: Mentor Type | B7: Prompt Count | C7: Response Count | D7: Coverage % | E7: Status
A8: PSP | B8: =COUNTA('PSP Mentor Prompts'!B:B)-1 -> 44 | C8: =COUNTA('PSP Mentor Prompts'!C:C)-1 -> 44 | D8: =IF(B8=0,0,C8/B8*100) -> 100 | E8: =IF(D8>=90,"Excellent",IF(D8>=70,"Good",IF(D8>=50,"Fair","Needs Attention"))) -> Excellent
A9: VSM | B9: =COUNTA('VSM Mentor Prompts'!B:B)-1 -> 31 | C9: =COUNTA('VSM Mentor Prompts'!C:C)-1 -> 31 | D9: =IF(B9=0,0,C9/B9*100) -> 100 | E9: =IF(D9>=90,"Excellent",IF(D9>=70,"Good",IF(D9>=50,"Fair","Needs Attention"))) -> Excellent
A10: TPI | B10: =COUNTA('TPI Mentor Prompts'!B:B)-1 -> 21 | C10: =COUNTA('TPI Mentor Prompts'!C:C)-1 -> 21 | D10: =IF(B10=0,0,C10/B10*100) -> 100 | E10: =IF(D10>=90,"Excellent",IF(D10>=70,"Good",IF(D10>=50,"Fair","Needs Attention"))) -> Excellent
A11: TOTAL | B11: =SUM(B8:B10) -> 96 | C11: =SUM(C8:C10) -> 96 | D11: =IF(B11=0,0,C11/B11*100) -> 100 | E11: Combined
A14: Mentor | B14: Percentage
A15: PSP | B15: =IF(B11=0,0,B8/B11*100) -> 45.833333
A16: 📋 LIVE METRICS SUMMARY
A17: TPI | B17: =IF(B11=0,0,B10/B11*100) -> 21.875
A18: Total Core Mentors: | B18: 3
A19: Total Prompts: | B19: =B11 -> 96
A20: Total Responses: | B20: =C11 -> 96
A21: Overall Coverage: | B21: =D11 -> 100
A22: Average per Mentor: | B22: =B11/3 -> 32
A23: Top Performer: | B23: =INDEX(A8:A10,MATCH(MAX(B8:B10),B8:B10,0)) -> PSP
A35: 💡 HOW IT WORKS:
A36: ✅ This dashboard updates AUTOMATICALLY when you change data in mentor sheets
A37: ✅ Add/remove prompts in PSP/VSM/TPI sheets - dashboard reflects changes instantly
A38: ✅ Charts and metrics recalculate automatically - no Python script needed
A39: ✅ Coverage percentages update as you add responses
A40: ✅ Top performer automatically changes based on current data

Sheet Charts Dashboard
A1: CORE MENTORS ANALYTICS DASHBOARD
A2: VSM | PSP | TPI Mentors Only | Generated: 2025-09-02 12:14:39
A4: 📊 SECTION 1: CORE MENTORS OVERVIEW
A6: Mentor Type | B6: Prompt Count | C6: Percentage
A7: PSP | B7: 44 | C7: 45.8%
A8: VSM | B8: 31 | C8: 32.3%
A9: TPI | B9: 21 | C9: 21.9%
A10: TOTAL | B10: 96 | C10: 100.0%
A29: 📈 SECTION 2: RESPONSE COVERAGE - CORE MENTORS
A31: Mentor Type | B31: Total Prompts | C31: Responses | D31: Coverage % | E31: Status
A32: PSP | B32: 44 | C32: 44 | D32: 100.0% | E32: Excellent
A33: VSM | B33: 31 | C33: 31 | D33: 100.0% | E33: Excellent
A34: TPI | B34: 21 | C34: 21 | D34: 100.0% | E34: Excellent
A54: 🎯 SECTION 3: PERFORMANCE COMPARISON - CORE MENTORS
A56: Mentor Type | B56: Prompts | C56: Coverage % | D56: Performance Score | E56: Rank
A57: PSP | B57: 44 | C57: 100.0% | D57: 100.0 | E57: 🥇 1
A58: VSM | B58: 31 | C58: 100.0% | D58: 82.3 | E58: 🥈 2
A59: TPI | B59: 21 | C59: 100.0% | D59: 68.6 | E59: 🥉 3
A79: 📋 CORE MENTORS EXECUTIVE SUMMARY
A81: Core Mentors Analyzed: | B81: PSP, VSM, TPI
A82: Total Prompts (Core): | B82: 96
A83: Average per Mentor: | B83: 32.0
A84: Average Coverage: | B84: 100.0%
A85: Top Performer: | B85: PSP (44 prompts)
A86: Analysis Date: | B86: 2025-09-02 12:14
A87: Data Quality: | B87: High - Core mentors only
A88: Filtered Out: | B88: New_Prompts, G&I (inactive)

Sheet PSP Mentor Prompts
A1: SL | B1: Prompts | C1: Response | D1: Sources | E1: Status | F1: Tester Remarks | G1: Developer Remarks | H1: Date
A2: 1 | B2: Upload my PSR and critique it | C2: To effectively critique your Problem Solving Report (PSR), we need to consider several key aspects based on the Fortive Business System (FBS) and the Problem Solving Process (PSP). Here’s a structured approach to evaluating your PSR: ### Key Components of a Problem Solving Report (PSR) 1. **Clarity of Problem Statement**: - Ensure that the problem statement is clearly defined. It should articulate the gap between the current state and the desired state. For example, if the issue is related to production downtime, specify the current downtime percentage and the target percentage. 2. **Artifacts and Insights**: - The PSR should include various artifacts that capture insights and learnings from the DIVE process. This could include data analysis, brainstorming results, and any relevant metrics. For instance, if you conducted a root cause analysis, summarize the findings and how they inform your next steps. 3. **Actions Taken**: - Document the actions that have been implemented to address the problem. This should include both immediate actions and long-term strategies. For example, if a quality defect was identified, detail the corrective actions taken and any preventive measures planned. 4. **Progress Tracking**: - Include metrics that track progress towards resolving the problem. This could be in the form of KPIs (Key Performance Indicators) relevant to your issue. For example, if you are addressing customer churn, include metrics like retention rates before and after implementing changes. 5. **Next Steps and Follow-Up**: - Clearly outline the next steps in the problem-solving process. This should include who is responsible for each action and the timeline for completion. For instance, if further analysis is needed, specify who will conduct it and by when. ### Example Critique Framework - **Problem Statement**: Is it specific and measurable? Does it clearly define the gap? - **Data and Artifacts**: Are the insights well-documented? Do they support the problem statement? - **Actions**: Are the actions taken logical and relevant? Are they documented with timelines? - **Metrics**: Are the metrics used to track progress appropriate and clearly presented? - **Next Steps**: Are the next steps actionable and assigned to specific team members? ### Conclusion By ensuring that your PSR addresses these components, you can enhance its effectiveness as a communication tool within the PSP framework. This will not only help in closing the gap between the current and desired states but also facilitate better collaboration and understanding among team members. If you would like to share specific sections of your PSR for a more detailed critique, please upload it, and I can provide targeted feedback based on the criteria outlined above. Would you like to proceed with that? | D2: https://fortive.sharepoint.com/:p:/r/sites/FTV-TheFort/_layouts/15/Doc.aspx?sourcedoc=%7B78185926-2BBA-4280-8D70-52802D36723D%7D&file=PSP%20tied%20to%20elearning.pptx&action=edit&mobileredirect=true | E2: Bad | F2: P.Lee: This is a prompt and the quality of the answer is dependent on the PSR loaded and if it is answering it correctly to actutally critique it. The prompt and the answer does not align. The prompt seems to ask to upload and reads the PSR. This should be the last one we test because this is dependent on the different scenarios and different version of PSR that gets upload be critiqued. I dont know how well the AI does it's critiquing ability yet.
A3: 2 | B3: Generate 7 ways to come up with a Pareto | C3: Creating a Pareto Chart is an effective way to visualize and prioritize problems based on the 80/20 rule, which helps teams focus on the most significant issues impacting their processes. Here are seven ways to develop a Pareto Chart, incorporating the principles from the Fortive Business System (FBS): ### 1. **Identify the Problem Area** - **Action**: Begin by clearly defining the problem you want to analyze. This could be related to quality defects, customer complaints, or production delays. - **Example**: If you are experiencing high customer churn, specify that as your problem area. ### 2. **Collect Data** - **Action**: Gather relevant data that reflects the frequency or impact of the issues within the defined problem area. This data can come from various sources such as customer feedback, production logs, or quality reports. - **Example**: For customer churn, collect data on the reasons customers cite for leaving, such as service issues, pricing, or product quality. ### 3. **Categorize the Data** - **Action**: Organize the collected data into categories that represent the different types of issues or causes. This helps in identifying patterns. - **Example**: Categorize reasons for churn into groups like "Service Quality," "Pricing," "Product Features," etc. ### 4. **Count the Frequency of Each Category** - **Action**: Tally the occurrences of each category to determine which issues are most prevalent. This step is crucial for creating the visual representation of the Pareto Chart. - **Example**: If "Service Quality" accounts for 50 complaints, "Pricing" for 30, and "Product Features" for 20, these counts will form the basis of your chart. ### 5. **Calculate Cumulative Percentages** - **Action**: Calculate the cumulative percentage of each category to visualize the impact of each issue relative to the total. This helps in identifying the most significant contributors. - **Example**: If the total number of complaints is 100, "Service Quality" would represent 50%, "Pricing" 30%, and "Product Features" 20%. The cumulative percentages would help illustrate how these categories contribute to the overall problem. ### 6. **Create the Pareto Chart** - **Action**: Using the frequency and cumulative percentage data, create the Pareto Chart. The left axis typically represents the frequency of issues, while the right axis represents the cumulative percentage. - **Example**: Plot the categories on the x-axis and their corresponding frequencies on the y-axis, adding a line graph for cumulative percentages. ### 7. **Analyze and Prioritize Actions** - **Action**: Review the completed Pareto Chart to identify the "vital few" issues that contribute to the majority of the problems. Focus your problem-solving efforts on these areas for maximum impact. - **Example**: If "Service Quality" is identified as the most significant issue, prioritize actions to improve service processes, training, or customer support. ### Conclusion By following these steps, you can effectively create a Pareto Chart that highlights the most critical issues within your problem area. This visual tool not only aids in understanding where to focus efforts but also aligns with the FBS principles of delivering extraordinary results and closing the gap between current and desired states. If you need further assistance in creating a specific Pareto Chart or analyzing your data, feel free to ask! Would you like to explore any of these steps in more detail? | D3: https://fortive.sharepoint.com/:p:/r/sites/FTV-TheFort/_layouts/15/Doc.aspx?sourcedoc=%7B78185926-2BBA-4280-8D70-52802D36723D%7D&file=PSP%20tied%20to%20elearning.pptx&action=edit&mobileredirect=true | E3: Bad | F3: P.Lee: The prompt and and answer is not related. The prompt assumption is I am uploading a dataset to go with it. Then the ask is to generate different ways to slice the data. The answer is more of an answer on different steps to consider when trying to create a Pareto.
A4: 3 | B4: Please generate 20 questions that I should ask that will help me dig deeper and gain insights on my problem | C4: To effectively dig deeper into a problem and gain valuable insights, it's essential to ask targeted questions that align with the Problem Solving Process (PSP) as outlined in the Fortive Business System (FBS). Here are 20 questions categorized into different areas that can help you explore the problem comprehensively: ### Understanding the Problem 1. **What is the specific problem we are facing?** - Clarifies the issue at hand. 2. **What are the symptoms of this problem?** - Helps identify observable effects. 3. **What is the gap between the current state (Actual) and the desired state (Standard)?** - Establishes a clear understanding of the discrepancy. 4. **When did this problem first occur?** - Provides context and timeline for the issue. 5. **How frequently does this problem occur?** - Assesses the severity and impact of the problem. ### Analyzing Causes 6. **What are the potential root causes of this problem?** - Encourages exploration of underlying issues. 7. **Who is affected by this problem, and how?** - Identifies stakeholders and their experiences. 8. **What data do we have that supports our understanding of this problem?** - Prompts review of existing evidence. 9. **Are there any patterns or trends associated with this problem?** - Looks for recurring themes or correlations. 10. **What assumptions are we making about this problem?** - Challenges preconceived notions that may hinder analysis. ### Exploring Solutions 11. **What solutions have we tried in the past, and what were the outcomes?** - Evaluates previous efforts and their effectiveness. 12. **What resources do we have available to address this problem?** - Assesses capabilities and constraints. 13. **What would success look like if we resolved this problem?** - Defines clear objectives for resolution. 14. **Who needs to be involved in the problem-solving process?** - Identifies key team members and stakeholders. 15. **What are the potential risks associated with different solutions?** - Considers the implications of various approaches. ### Implementing and Sustaining Solutions 16. **How will we measure the success of our solution?** - Establishes metrics for evaluation. 17. **What is the timeline for implementing potential solutions?** - Sets expectations for progress. 18. **How will we communicate our findings and solutions to the team?** - Ensures transparency and collaboration. 19. **What steps will we take to sustain improvements once implemented?** - Focuses on long-term success and prevention of recurrence. 20. **How will we gather feedback after implementing the solution?** - Plans for ongoing assessment and adjustment. ### Conclusion These questions are designed to guide you through a thorough exploration of your problem, aligning with the PSP framework to ensure that you identify the root causes and develop effective solutions. By systematically addressing these areas, you can close the gap between your current state and desired outcomes, ultimately delivering extraordinary results. If you would like to discuss any specific questions further or need assistance in applying these questions to your situation, feel free to ask! Would you like to explore any particular area in more detail? | D4: https://fortive.sharepoint.com/:p:/r/sites/FTV-TheFort/_layouts/15/Doc.aspx?sourcedoc=%7B2679DEA0-53E4-46A4-80CC-69F4534B9231%7D&file=fortive-problem-solving-process-%20tied%20to%20elearning.pptx&action=edit&mobileredirect=true | E4: Neutral | F4: P.Lee: The prompt is asking questions about how to generate more insights on the problem statement. The insights provided on the "Understanding the Problem" + "possibly the causes" are OK but the comments after that does not relate to the question. Solutions and sustainment of them is not what the prompt is asking for. the question is on the D in the DIVE and we are giving answers about "I&V" section. REsponses like : I can provide you with general guidelines and questions to consider, See below .... then ask if they can share the problem statement we can create a more specific set of questions to consider.
A5: 4 | B5: Can you create a level 1 and level 2 pareto? | C5: Creating Level 1 and Level 2 Pareto Charts is an effective way to analyze problems and identify their root causes using the 80/20 rule, as established by Vilfredo Pareto. Below is a structured approach to developing both types of Pareto Charts, incorporating the principles from the Fortive Business System (FBS). ### Level 1 Pareto Chart **Purpose**: The Level 1 Pareto Chart helps identify where the problems are occurring by categorizing and quantifying the frequency of issues. #### Steps to Create a Level 1 Pareto Chart: 1. **Identify the Problem Area**: - Define the specific problem you want to analyze. For example, if you are experiencing quality defects in a manufacturing process, specify that as your focus. 2. **Collect Data**: - Gather data on the frequency of different types of defects or issues. This could come from quality control reports, customer complaints, or production logs. - **Example Data**: - Defect Type A: 50 occurrences - Defect Type B: 30 occurrences - Defect Type C: 20 occurrences - Defect Type D: 10 occurrences 3. **Categorize the Data**: - Organize the data into categories based on the types of defects or issues identified. 4. **Create the Chart**: - Plot the categories on the x-axis and the frequency of occurrences on the y-axis. Use bars to represent the frequency of each defect type. - Add a cumulative percentage line to show the cumulative impact of the issues. 5. **Analyze the Chart**: - Identify the "vital few" issues that contribute to the majority of the problems. For instance, if Defect Type A accounts for 50% of the total defects, it should be prioritized for resolution. ### Level 2 Pareto Chart **Purpose**: The Level 2 Pareto Chart focuses on understanding why the problems are occurring by analyzing the root causes. #### Steps to Create a Level 2 Pareto Chart: 1. **Build on Level 1 Findings**: - Use the insights gained from the Level 1 Pareto Chart to identify potential root causes for the most significant issues. 2. **Identify the "WHY"**: - Each team member should brainstorm and identify at least five different potential causes for the top issues identified in the Level 1 chart. - **Example Causes for Defect Type A**: - Lack of training for operators - Inadequate maintenance of equipment - Poor quality of raw materials - Inefficient production processes - Lack of quality checks 3. **Create an Affinity Diagram**: - Organize the identified causes into an affinity diagram to group similar ideas and identify patterns. 4. **Select Top Causes**: - As a team, select the top two most insightful causes based on the affinity diagram. These will be the focus for further analysis. 5. **Collect Data for Selected Causes**: - Gather data to support the analysis of these root causes. This could include training records, maintenance logs, or supplier quality reports. 6. **Create the Level 2 Pareto Chart**: - Plot the selected root causes on the x-axis and their frequency or impact on the y-axis. This chart will help visualize which root causes are most significant. 7. **Analyze and Plan Actions**: - Use the Level 2 Pareto Chart to prioritize actions that address the root causes. For example, if "Lack of training for operators" is identified as a major cause, develop a training program to mitigate this issue. ### Conclusion By following these steps, you can effectively create both Level 1 and Level 2 Pareto Charts that will help you understand where problems are occurring and why they are happening. This structured approach aligns with the Problem Solving Process (PSP) and supports continuous improvement efforts within the Fortive Business System. If you need further assistance in applying these steps to a specific problem or creating the charts, feel free to ask! Would you like to explore any particular aspect in more detail? | D5: https://fortive.sharepoint.com/:p:/r/sites/FTV-TheFort/_layouts/15/Doc.aspx?sourcedoc=%7B78185926-2BBA-4280-8D70-52802D36723D%7D&file=PSP%20tied%20to%20elearning.pptx&action=edit&mobileredirect=true | E5: Neutral | F5: P.LEE: The prompt is can you create a L1 & L2 Pareto. Answer should be "YES" and but they need to load the excel data so KATA mentor can do it. Prompt wasn’t asking what a L1 and L2 is or what the steps are to create one. Should ask if they would like to know if they want to know the difference between the 2 or the steps to create one.
A6: 5 | B6: What gemba evidence do I need to support the 5 why I just created? | C6: To effectively support the "5 Whys" analysis with Gemba evidence, it’s essential to gather data and observations that directly relate to the identified root causes of the problem. Gemba, which means "the real place" in Japanese, emphasizes going to the location where the work is done to observe processes and gather firsthand information. Here’s how to approach collecting Gemba evidence to support your analysis: ### 1. **Observation of Processes** - **Action**: Spend time observing the specific processes related to the problem. Look for inefficiencies, bottlenecks, or deviations from standard operating procedures. - **Example**: If the issue is related to production delays, observe the production line to identify where delays occur and what factors contribute to them (e.g., equipment malfunctions, operator errors). ### 2. **Engagement with Employees** - **Action**: Talk to employees who are directly involved in the processes. Their insights can provide valuable context and highlight issues that may not be immediately visible. - **Example**: Ask operators about their experiences with the equipment or processes. They may reveal that a specific machine frequently breaks down or that they lack the necessary training to perform their tasks efficiently. ### 3. **Review of Performance Metrics** - **Action**: Collect and analyze relevant performance metrics that can provide quantitative evidence of the problem. - **Example**: Look at key performance indicators (KPIs) such as cycle times, defect rates, or downtime statistics. If you find that defect rates have increased, this data can support your analysis of why quality issues are occurring. ### 4. **Documentation of Standard Procedures** - **Action**: Compare current practices with documented standard operating procedures (SOPs) to identify discrepancies. - **Example**: If the SOP states that a particular quality check should be performed at a specific stage, but it is not being done, this evidence can help explain why defects are occurring. ### 5. **Analysis of Historical Data** - **Action**: Review historical data related to the problem to identify trends or recurring issues. - **Example**: If you notice that a particular defect type has been increasing over time, this historical evidence can support your findings in the "5 Whys" analysis. ### 6. **Visual Evidence** - **Action**: Take photographs or videos of the processes, equipment, or areas where problems are occurring. Visual evidence can be compelling in illustrating issues. - **Example**: If there are safety hazards or cluttered workspaces contributing to inefficiencies, visual documentation can highlight these problems effectively. ### 7. **Feedback from Customers** - **Action**: Gather feedback from customers regarding their experiences with the product or service. This can provide insights into external perceptions of the problem. - **Example**: If customers report issues with product quality, this feedback can support your analysis of why quality checks may be failing. ### Conclusion By collecting this Gemba evidence, you will be able to substantiate the findings from your "5 Whys" analysis with concrete data and observations. This approach aligns with the Problem Solving Process (PSP) and helps ensure that your solutions are grounded in reality, ultimately leading to more effective problem resolution. If you need further assistance in gathering specific types of Gemba evidence or applying these concepts to your situation, feel free to ask! Would you like to explore any particular aspect in more detail? | D6: https://fortive.sharepoint.com/:p:/r/sites/FTV-TheFort/_layouts/15/Doc.aspx?sourcedoc=%7B2679DEA0-53E4-46A4-80CC-69F4534B9231%7D&file=fortive-problem-solving-process-%20tied%20to%20elearning.pptx&action=edit&mobileredirect=true | E6: Good | F6: P.Lee: It is providing different ways or examples on obtaining Gemba evidence.
A7: 6 | B7: Does my logic of my 5 whys makes sense to get to my root cause? Please analyze and provide feedback | C7: To analyze the logic of your "5 Whys" and provide feedback on whether it effectively leads to the root cause, we can follow a structured approach based on the principles of the Problem Solving Process (PSP) within the Fortive Business System (FBS). Here’s how to evaluate your analysis: ### 1. **Clarity of the Problem Statement** - **Assessment**: Ensure that your initial problem statement is clear and specific. It should define the gap between the current state (Actual) and the desired state (Standard). - **Example**: If your problem statement is "Production delays are occurring," clarify what the expected production rate is versus the actual rate. ### 2. **Logical Flow of the 5 Whys** - **Assessment**: Each "Why" should logically lead to the next question, progressively digging deeper into the causes of the problem. - **Example**: - **Why are we experiencing production delays?** (e.g., Equipment breakdown) - **Why is the equipment breaking down?** (e.g., Lack of maintenance) - **Why is there a lack of maintenance?** (e.g., Insufficient training for maintenance staff) - **Why is there insufficient training?** (e.g., No training program in place) - **Why is there no training program?** (e.g., Budget constraints) ### 3. **Validation of Causes** - **Assessment**: Each identified cause should be validated with evidence, ideally through Gemba observations or data analysis. This ensures that the identified causes are not assumptions but are based on real observations. - **Example**: If you state that "lack of maintenance" is a cause, provide evidence from maintenance logs or interviews with maintenance staff that supports this claim. ### 4. **Limiting to Actual Causes** - **Assessment**: The final causes identified should be limited to no more than three actual causes, as recommended in the FBS methodology. This helps focus efforts on the most impactful areas. - **Example**: If your final causes are "lack of training" and "budget constraints," ensure these are the most significant contributors to the problem. ### 5. **Alignment with PSP Framework** - **Assessment**: Ensure that your "5 Whys" analysis aligns with the overall PSP framework, which emphasizes understanding the problem, identifying root causes, and planning actions to close the gap. - **Example**: After identifying the root causes, outline specific actions that can be taken to address them, such as developing a training program or reallocating budget resources. ### Conclusion and Feedback If your "5 Whys" follow a logical progression, are supported by evidence, and lead to a limited number of actual causes, then your analysis is sound and effectively identifies the root cause. If any of these elements are lacking, consider revisiting those areas to strengthen your analysis. If you would like to share your specific "5 Whys" for a more detailed review or need assistance in refining your logic, feel free to provide that information! Would you like to explore any particular aspect further? | D7: https://fortive.sharepoint.com/:p:/r/sites/FTV-TheFort/_layouts/15/Doc.aspx?sourcedoc=%7B2679DEA0-53E4-46A4-80CC-69F4534B9231%7D&file=fortive-problem-solving-process-%20tied%20to%20elearning.pptx&action=edit&mobileredirect=true | E7: Bad | F7: P.LEE this is not a generic prompt that can be answered with a standard answser, the 5 why's is dependendent on the PSR loaded. Not a good prompt to use. Unless the prompt is changed to "What are charateristics of a good 5 why" might be closer to the answer on column C
A8: 7 | B8: how should I look at things differently if it is a Caused vs. a Created problem? | C8: Understanding the distinction between "Caused" and "Created" problems is crucial in the Problem Solving Process (PSP) within the Fortive Business System (FBS). This differentiation influences how you approach problem analysis and resolution. Here’s how to look at these two types of problems differently: ### 1. **Definition of Terms** - **Caused Problems**: These are issues that arise from external factors or events outside of the system or process. They are typically beyond the control of the organization and can include things like supply chain disruptions, regulatory changes, or natural disasters. - **Created Problems**: These are internal issues that stem from the organization’s own processes, systems, or decisions. They often result from inefficiencies, poor practices, or lack of adherence to standards. ### 2. **Approach to Problem Analysis** - **For Caused Problems**: - **Focus on External Factors**: Investigate the external circumstances that led to the problem. This may involve analyzing market conditions, supplier performance, or environmental factors. - **Example**: If a production line is halted due to a supplier failing to deliver materials on time, the problem is caused by the supplier's actions, not by internal processes. - **Action**: Develop contingency plans or alternative sourcing strategies to mitigate the impact of external disruptions. - **For Created Problems**: - **Focus on Internal Processes**: Analyze the internal systems and practices that contributed to the problem. This may involve reviewing workflows, employee training, or adherence to standard operating procedures. - **Example**: If a quality defect occurs due to improper training of staff on equipment usage, the problem is created by the organization’s training processes. - **Action**: Implement process improvements, such as enhanced training programs or revised standard operating procedures, to prevent recurrence. ### 3. **Root Cause Analysis** - **For Caused Problems**: - **Use External Data**: Gather data from external sources to understand the context of the problem. This could include market analysis reports, supplier performance metrics, or industry benchmarks. - **Example**: Analyzing market trends that led to increased demand for a product can help understand why a supplier was unable to meet delivery timelines. - **For Created Problems**: - **Conduct Internal Assessments**: Utilize tools like the "5 Whys" or Pareto analysis to identify root causes within the organization. Engage with employees at the Gemba to gather insights on process inefficiencies. - **Example**: If a defect is traced back to a lack of quality checks, the root cause analysis should focus on the quality control processes in place. ### 4. **Solution Development** - **For Caused Problems**: - **Develop Adaptive Strategies**: Solutions may involve adapting to external changes, such as finding new suppliers or adjusting production schedules based on market conditions. - **Example**: If a natural disaster affects supply chains, consider diversifying suppliers or increasing inventory levels to buffer against future disruptions. - **For Created Problems**: - **Implement Process Improvements**: Solutions should focus on improving internal processes, enhancing training, or refining workflows to eliminate the root causes. - **Example**: If employee errors are leading to defects, a solution could involve implementing a more robust training program and regular performance reviews. ### Conclusion By recognizing whether a problem is caused by external factors or created by internal processes, you can tailor your analysis and solutions accordingly. This distinction is vital for effective problem-solving and aligns with the PSP framework, enabling you to close the gap between the current state and desired outcomes. If you have specific examples of problems you are facing, feel free to share them for more tailored guidance! Would you like to explore any particular aspect further? | D8: https://fortive.sharepoint.com/:p:/r/sites/FTV-TheFort/_layouts/15/Doc.aspx?sourcedoc=%7B2679DEA0-53E4-46A4-80CC-69F4534B9231%7D&file=fortive-problem-solving-process-%20tied%20to%20elearning.pptx&action=edit&mobileredirect=true | E8: Bad | F8: P.Lee: This is a main question, and the answer is saying caused problems are all caused by issues beyond our control. And created is focusing on internal processes which is wrong. Should review where we are getting the info and if we need to correct it somewhere if it is indicating that. The new PSP deck has it all spelled out too why it is called Caused vs. Created and with distinct definitions https://fortive.sharepoint.com/sites/FBS/SiteAssets/SitePages/PSP/PSP-Facilitator-Deck-2025--Final.pptx?web=1
A9: 8 | B9: Create a Run chart that graphically helps show case the timing of of the problem | C9: Creating a Run Chart is an effective way to visualize the timing of a problem, helping to identify trends, patterns, and anomalies over time. Below is a structured approach to creating a Run Chart, incorporating the principles from the Fortive Business System (FBS). ### Steps to Create a Run Chart 1. **Define the Problem Statement Using TAGS** - **TAGS Framework**: Ensure you have a clear problem statement that includes: - **Target**: The desired outcome or standard. - **Actual**: The current performance or measurement. - **Gap**: The difference between the target and actual performance. - **Scope**: The context or boundaries of the problem. - **Example**: If the problem is related to production delays, your TAGS might look like this: - **Target**: 95% on-time delivery - **Actual**: 85% on-time delivery - **Gap**: 10% - **Scope**: Production line A over the last quarter. 2. **Collect Data** - Gather data points that reflect the performance over time. This data should be collected in the same units as used in your TAGS statement. - **Example Data**: Collect weekly on-time delivery percentages for the last 12 weeks: - Week 1: 90% - Week 2: 85% - Week 3: 80% - Week 4: 88% - Week 5: 82% - Week 6: 75% - Week 7: 87% - Week 8: 80% - Week 9: 78% - Week 10: 85% - Week 11: 83% - Week 12: 90% 3. **Set Up the Run Chart** - **X-Axis**: Represent time (e.g., weeks). - **Y-Axis**: Represent the performance metric (e.g., on-time delivery percentage). - **Plot the Data**: Mark each data point on the chart according to the week and the corresponding on-time delivery percentage. 4. **Add Reference Lines** - **Target Line**: Draw a horizontal line at the target percentage (e.g., 95%). - **Average Line**: Optionally, calculate and draw a line representing the average performance over the period. - **Example**: If the average on-time delivery over the 12 weeks is 82%, draw a horizontal line at 82%. 5. **Analyze the Chart** - Look for trends, spikes, or drops in performance. Identify any patterns that correlate with specific events or changes in the process. - **Example Analysis**: If you notice a significant drop in on-time delivery in Week 6, investigate what occurred during that week (e.g., equipment failure, staffing issues). ### Example of a Run Chart Here’s a simplified representation of how your Run Chart might look: ``` On-Time Delivery Percentage 100% | 95% |------------------- Target Line -------- 90% | * * * 85% | * * * * 80% | * * * * 75% | * * * * 70% |___________________________________________ Week 1 Week 2 Week 3 Week 4 Week 5 Week 6 Week 7 Week 8 Week 9 Week 10 Week 11 Week 12 ``` ### Conclusion By following these steps, you can create a Run Chart that visually represents the timing of the problem and helps identify trends and potential causes. This aligns with the PSP framework, allowing you to analyze the gap between your actual performance and desired outcomes effectively. If you need further assistance in creating the chart or analyzing specific data points, feel free to ask! Would you like to explore any particular aspect further? | D9: https://fortive.sharepoint.com/:p:/r/sites/FTV-TheFort/_layouts/15/Doc.aspx?sourcedoc=%7B2679DEA0-53E4-46A4-80CC-69F4534B9231%7D&file=fortive-problem-solving-process-%20tied%20to%20elearning.pptx&action=edit&mobileredirect=true | E9: Bad | F9: P.Lee This is not a good prompt without any data uploaded, in order to test this, the same data file should be loaded to compare if it is still providing you with the consistent answer. Asking it the way it is not helpful to see if it is working, all you can validate is it is responding. better prompt question might be "what are the steps in creating a run chart?" , "how do I create a run chart?" , or "what should I be looking out for when I create a run chart?" Questions that will provide consistent answers not situational TAGS: TREND, ACTUAL, GAP, STANDARD - Not Target, Actual, Gap. Scope
A10: 9 | B10: what is a glide path and how do I create an action plan that can support the timing? | C10: A **glide path** is a strategic plan that outlines the steps and timeline necessary to achieve a specific goal or improvement target. It provides a clear trajectory for progress, ensuring that actions are aligned with desired outcomes and that stakeholders understand the timing and expectations involved. In the context of the Fortive Business System (FBS) and the Problem Solving Process (PSP), creating an effective action plan that supports the glide path is essential for successful implementation. ### Steps to Create an Action Plan that Supports the Glide Path 1. **Define the Improvement Priority** - **Action**: Clearly identify the specific process or area that needs improvement. This should be based on data analysis, such as findings from a Kaizen event or a run chart. - **Example**: If the goal is to reduce production downtime, specify that as your improvement priority. 2. **Set Clear Objectives** - **Action**: Establish measurable objectives that align with the glide path. These should be specific, measurable, achievable, relevant, and time-bound (SMART). - **Example**: Reduce production downtime by 20% within the next quarter. 3. **Identify Key Actions** - **Action**: List the specific actions required to achieve the objectives. Each action should contribute directly to closing the gap between the current state and the desired state. - **Example**: - Conduct a root cause analysis of downtime incidents. - Implement a preventive maintenance schedule. - Train staff on equipment operation and maintenance. 4. **Assign Responsibilities** - **Action**: Designate an action plan owner for each task. This ensures accountability and clarity regarding who is responsible for each action. - **Example**: Assign the maintenance manager to oversee the implementation of the preventive maintenance schedule. 5. **Establish a Timeline** - **Action**: Create a timeline for each action, indicating when it should start and when it should be completed. This timeline should align with the glide path, ensuring that all actions are scheduled to support the overall goal. - **Example**: - Root cause analysis: Start in Week 1, complete by Week 2. - Preventive maintenance schedule: Develop by Week 3, implement by Week 4. - Staff training: Schedule for Week 5. 6. **Monitor Progress** - **Action**: Set up regular check-ins to monitor progress against the glide path. This allows for adjustments to be made if necessary and ensures that the team stays on track. - **Example**: Weekly meetings to review progress on action items and discuss any challenges. 7. **Document and Communicate** - **Action**: Document the action plan in a clear format, including all the elements above. Share this document with all stakeholders to ensure transparency and alignment. - **Example**: Use a table format to outline the action plan, including columns for the improvement priority, action items, responsible parties, timelines, and comments. ### Example Action Plan Table | Improvement Priority | Action Item | Action Plan Owner | Timing | Comments/Specific Time | |------------------------------|------------------------------------------|-------------------|-----------------------|---------------------------------| | Reduce Production Downtime | Conduct root cause analysis | Maintenance Manager| Week 1 - Week 2 | Analyze downtime incidents | | | Implement preventive maintenance schedule | Maintenance Manager| Week 3 - Week 4 | Schedule maintenance tasks | | | Train staff on equipment operation | Training Coordinator| Week 5 | Develop training materials | ### Conclusion By following these steps, you can create a comprehensive action plan that supports the glide path for your improvement initiative. This structured approach ensures that all actions are aligned with the desired outcomes and that progress is monitored effectively, ultimately leading to successful implementation of improvements within the Fortive Business System. If you need further assistance in developing specific elements of your action plan or have questions about the glide path concept, feel free to ask! Would you like to explore any particular aspect further? | D10: https://fortive.sharepoint.com/:p:/r/sites/FTV-TheFort/_layouts/15/Doc.aspx?sourcedoc=%7B2679DEA0-53E4-46A4-80CC-69F4534B9231%7D&file=fortive-problem-solving-process-%20tied%20to%20elearning.pptx&action=edit&mobileredirect=true | E10: Neutral | F10: P.Lee: Is there a reference somewhere in the PSP training deck on SMART objectives? A picture of a glide path would be very helpful here. The action plan answers are good and I do like the timeline creation part. A key piece of info that should point out and usually used during the DEFINE state and the VERIFY stages of the DIVE process. During the DEFINE Stage, the glide path shows where we will end up after a certime time frame if we continue at the current course. During the VERIFY stage, after we identify the CM to the root causes, it visually shows of the CM identified is sufficient to eliminate the gap at the timeframe needed. If not, then additional CM might be needed.
A11: 10 | B11: on the DEFINE stage, what are the key things that I need to be on a look out for? | C11: In the DEFINE stage of the Problem Solving Process (PSP) within the Fortive Business System (FBS), it is crucial to establish a clear understanding of the problem at hand. This stage sets the foundation for effective problem resolution and involves several key elements that you should be on the lookout for: ### 1. **Clear Problem Statement** - **Action**: Formulate a concise and specific problem statement that captures the essence of the issue. This statement should articulate the gap between the current state (Actual) and the desired state (Standard). - **Example**: Instead of saying "Production is slow," a clearer problem statement would be "Production line A is operating at 70% efficiency, while the target efficiency is 90%, resulting in a 20% gap." ### 2. **Understanding the Scope** - **Action**: Define the boundaries of the problem. Identify what is in-scope and out-of-scope for the analysis to ensure that the focus remains on relevant factors. - **Example**: If the problem involves production delays, clarify whether you are focusing on a specific product line, shift, or time period. ### 3. **Data Collection** - **Action**: Gather relevant data that supports your understanding of the problem. This may include historical performance data, customer feedback, or operational metrics. - **Example**: Collect data on production rates, downtime incidents, and quality defects over the past few months to identify trends and patterns. ### 4. **Stakeholder Involvement** - **Action**: Engage with key stakeholders who are affected by or have insights into the problem. Their perspectives can provide valuable context and help validate the problem statement. - **Example**: Conduct interviews or surveys with operators, supervisors, and quality control personnel to gather insights on the challenges they face. ### 5. **Identifying the Impact** - **Action**: Assess the impact of the problem on the organization. This includes understanding how the problem affects productivity, quality, customer satisfaction, and overall business objectives. - **Example**: Determine how the 20% efficiency gap translates into lost revenue or increased costs, which can help prioritize the urgency of addressing the problem. ### 6. **Use of TAGS Framework** - **Action**: Utilize the TAGS framework (Target, Actual, Gap, Scope) to structure your problem definition. This framework helps ensure that all critical aspects of the problem are considered. - **Example**: - **Target**: 90% efficiency - **Actual**: 70% efficiency - **Gap**: 20% - **Scope**: Production line A for the last quarter. ### 7. **Run Chart Preparation** - **Action**: Prepare to create a run chart that visually represents the data over time. This chart will help illustrate trends and fluctuations related to the problem. - **Example**: Set up a run chart with time on the x-axis and production efficiency on the y-axis to visualize how performance has changed over the past months. ### Conclusion By focusing on these key elements during the DEFINE stage, you can establish a solid foundation for your problem-solving efforts. This clarity will guide subsequent stages of the PSP, ensuring that the team is aligned and equipped to address the identified issues effectively. If you have specific aspects of the DEFINE stage you would like to explore further or need assistance with a particular problem, feel free to ask! Would you like to dive deeper into any of these areas? | D11: https://fortive.sharepoint.com/:p:/r/sites/FTV-TheFort/_layouts/15/Doc.aspx?sourcedoc=%7B2679DEA0-53E4-46A4-80CC-69F4534B9231%7D&file=fortive-problem-solving-process-%20tied%20to%20elearning.pptx&action=edit&mobileredirect=true | E11: Neutral | F11: P.Lee all right answers, I think what is missing is the topic of RATIONALE and TEAM selection. It identifies the steps needed to create the TAGS, problem statement is good but the process in creating that should also be taken into consideration as this is a team sport and ensuring this is a problem worth solving.
A12: 11 | B12: on the INVESTIGATE stage, what are the key things that I need to be on a look out for? | C12: In the INVESTIGATE stage of the Problem Solving Process (PSP) within the Fortive Business System (FBS), the focus is on thoroughly analyzing the problem to identify its root causes. This stage is critical for ensuring that the solutions developed later are based on a comprehensive understanding of the issue. Here are the key elements to look out for during the INVESTIGATE stage: ### 1. **Data Collection** - **Action**: Gather relevant quantitative and qualitative data that pertains to the problem. This data should help illustrate the extent of the issue and provide insights into potential causes. - **Example**: If the problem is related to increased defect rates in production, collect data on defect types, frequencies, and any relevant operational metrics over a defined period. ### 2. **Observation at the Gemba** - **Action**: Go to the actual location where the problem occurs (Gemba) to observe processes firsthand. This allows you to see the problem in context and gather insights that may not be evident from data alone. - **Example**: Observe the production line during different shifts to identify patterns in defects or inefficiencies, and engage with operators to understand their experiences. ### 3. **Engagement with Stakeholders** - **Action**: Involve key stakeholders, including employees, supervisors, and customers, to gather diverse perspectives on the problem. Their insights can provide valuable context and help validate findings. - **Example**: Conduct interviews or focus groups with team members to discuss their observations and experiences related to the problem. ### 4. **Identifying Patterns and Trends** - **Action**: Analyze the collected data for patterns or trends that may indicate underlying issues. Look for correlations between different data points that could help identify root causes. - **Example**: If you notice that defect rates spike during specific shifts or after certain maintenance activities, this could indicate a need for further investigation into those areas. ### 5. **Utilizing Problem-Solving Tools** - **Action**: Employ various problem-solving tools and methodologies, such as the "5 Whys," Fishbone Diagram (Ishikawa), or Pareto Analysis, to systematically analyze the problem and identify root causes. - **Example**: Use a Fishbone Diagram to categorize potential causes of defects into categories such as People, Processes, Equipment, and Materials. ### 6. **Validation of Findings** - **Action**: Validate the identified causes with evidence. Ensure that the conclusions drawn from the investigation are supported by data and observations. - **Example**: If a lack of training is identified as a root cause, review training records and gather feedback from employees about their training experiences. ### 7. **Documentation of Insights** - **Action**: Document all findings, insights, and data collected during the investigation. This documentation will be crucial for the next stages of the PSP and for communicating findings to stakeholders. - **Example**: Create a report summarizing the investigation process, data analysis, and identified root causes, which can be shared with the team and leadership. ### Conclusion By focusing on these key elements during the INVESTIGATE stage, you can ensure a comprehensive understanding of the problem and its root causes. This thorough analysis will set the stage for effective problem resolution and align with the overall goals of the Fortive Business System. If you have specific aspects of the INVESTIGATE stage you would like to explore further or need assistance with a particular problem, feel free to ask! Would you like to dive deeper into any of these areas? | D12: https://fortive.sharepoint.com/:p:/r/sites/FTV-TheFort/_layouts/15/Doc.aspx?sourcedoc=%7B2679DEA0-53E4-46A4-80CC-69F4534B9231%7D&file=fortive-problem-solving-process-%20tied%20to%20elearning.pptx&action=edit&mobileredirect=true | E12: Neutral | F12: P.Lee: All correct answers but incomplete. During investigate the main step here is working on the Paretos and that should be a main topic, it is embedded in the **Utilizing Problem solving tools** Missing topics like 1)L1 Pareto in relation to Pareto 2 (a subset and there is linkage. 2) the cummulative %, what is acceptable?, 3the Pareto units of measure should be the same units as the GAP. 4) 5 whys logic making sense going forward and backward asking "BECAUSE" and "AS A RESULT/ THEREFORE"
A13: 12 | B13: On the VERIFY stage, what are the key things that I need to be on a look out for? | C13: In the VERIFY stage of the Problem Solving Process (PSP) within the Fortive Business System (FBS), the focus is on confirming that the implemented solutions effectively address the identified problems and that the desired outcomes are being achieved. This stage is critical for ensuring that the actions taken have led to meaningful improvements. Here are the key elements to look out for during the VERIFY stage: ### 1. **Establish Clear Metrics for Success** - **Action**: Define specific metrics that will be used to evaluate the effectiveness of the implemented solutions. These metrics should align with the objectives set during the DEFINE stage. - **Example**: If the goal was to reduce production downtime, metrics could include on-time delivery rates, production efficiency percentages, and the frequency of downtime incidents. ### 2. **Collect Data Post-Implementation** - **Action**: Gather data after the solutions have been implemented to assess their impact. This data should be compared against the baseline data collected prior to the implementation. - **Example**: If you implemented a new maintenance schedule, collect data on equipment downtime and production rates over a defined period after the changes were made. ### 3. **Analyze Results Against Targets** - **Action**: Analyze the collected data to determine whether the results meet the established targets. Look for trends and patterns that indicate whether the solutions are effective. - **Example**: If the target was to achieve a 20% reduction in downtime, calculate the actual reduction and assess whether it meets the target. ### 4. **Engage Stakeholders for Feedback** - **Action**: Involve key stakeholders, including team members and supervisors, to gather qualitative feedback on the changes. Their insights can provide context to the data and highlight any unforeseen issues. - **Example**: Conduct surveys or hold meetings to discuss how the changes have affected daily operations and whether any new challenges have arisen. ### 5. **Identify Any Unintended Consequences** - **Action**: Look for any unintended consequences that may have resulted from the implemented solutions. These could be negative impacts that were not anticipated during the planning phase. - **Example**: If a new process was introduced to speed up production, check if it has led to an increase in defects or employee dissatisfaction. ### 6. **Document Findings and Adjustments** - **Action**: Document all findings from the verification process, including successes, challenges, and any adjustments that need to be made. This documentation will be valuable for future problem-solving efforts. - **Example**: Create a report summarizing the results of the verification process, including data analysis, stakeholder feedback, and any necessary changes to the implemented solutions. ### 7. **Plan for Continuous Improvement** - **Action**: Use the insights gained during the VERIFY stage to inform future improvement initiatives. Continuous improvement is a core principle of the FBS, and lessons learned should be applied to ongoing processes. - **Example**: If certain aspects of the solution were effective while others were not, consider refining the approach and planning additional kaizen events to address remaining issues. ### Conclusion By focusing on these key elements during the VERIFY stage, you can ensure that the solutions implemented are effective and that the desired outcomes are being achieved. This thorough verification process aligns with the overall goals of the Fortive Business System and supports continuous improvement efforts. If you have specific aspects of the VERIFY stage you would like to explore further or need assistance with a particular problem, feel free to ask! Would you like to dive deeper into any of these areas? | D13: https://fortive.sharepoint.com/:p:/r/sites/FTV-TheFort/_layouts/15/Doc.aspx?sourcedoc=%7B2679DEA0-53E4-46A4-80CC-69F4534B9231%7D&file=fortive-problem-solving-process-%20tied%20to%20elearning.pptx&action=edit&mobileredirect=true | E13: Neutral | F13: P.Lee All correct and good answers but is missing a few key items. VERIFY stage,1) we need to ensure the CM identified is improving the GAP 2) ensure that we have enough CM to 3) ensure that there is Temporary and Permanent CM. 4) Target dates are not all at the end of the year, and there is sense of urgency to improve things. 5) CM will delivery results at the expected timeline by using the GLIDEPATH to visually see when will mitigate the gap.
A14: 13 | B14: on the ENSURE sustainment stage, what are the key things that I need to look out for? | C14: In the ENSURE sustainment stage of the Problem Solving Process (PSP) within the Fortive Business System (FBS), the focus is on maintaining the improvements achieved through previous stages and ensuring that the solutions implemented continue to deliver the desired results over time. This stage is critical for embedding changes into the organizational culture and preventing regression to old habits. Here are the key elements to look out for during the ENSURE sustainment stage: ### 1. **Standardization of Processes** - **Action**: Develop and document standard operating procedures (SOPs) that reflect the new processes and improvements. This ensures that everyone follows the same methods and practices. - **Example**: If a new maintenance schedule was implemented to reduce equipment downtime, create an SOP that outlines the maintenance tasks, frequency, and responsible personnel. ### 2. **Training and Development** - **Action**: Provide ongoing training for employees to ensure they are familiar with the new processes and understand their roles in sustaining improvements. - **Example**: Conduct training sessions for staff on the updated procedures and any new tools or technologies introduced during the improvement process. ### 3. **Monitoring and Measurement** - **Action**: Establish metrics and key performance indicators (KPIs) to continuously monitor the effectiveness of the implemented solutions. Regularly review these metrics to identify any deviations from expected performance. - **Example**: If the goal was to maintain a 20% reduction in downtime, track downtime metrics weekly and compare them against the target to ensure compliance. ### 4. **Feedback Mechanisms** - **Action**: Create channels for employees to provide feedback on the new processes. This can help identify issues early and allow for adjustments to be made as needed. - **Example**: Implement regular check-in meetings or anonymous surveys to gather input from team members about the effectiveness of the changes and any challenges they face. ### 5. **Leadership Engagement** - **Action**: Ensure that leadership remains engaged and supportive of the changes. Their commitment is crucial for fostering a culture of continuous improvement. - **Example**: Leaders should regularly communicate the importance of the changes and recognize team members who contribute to sustaining improvements. ### 6. **Continuous Improvement Culture** - **Action**: Foster a culture of continuous improvement where employees are encouraged to identify further opportunities for enhancement. This mindset helps sustain improvements and drives ongoing success. - **Example**: Encourage teams to hold regular kaizen events to explore new areas for improvement and to celebrate successes achieved through the changes. ### 7. **Regular Reviews and Audits** - **Action**: Schedule periodic reviews and audits of the processes to ensure compliance with the new standards and to assess the effectiveness of the improvements. - **Example**: Conduct quarterly audits to evaluate adherence to the new maintenance schedule and to identify any areas that may need additional support or adjustment. ### Conclusion By focusing on these key elements during the ENSURE sustainment stage, you can effectively maintain the improvements achieved through the PSP. This structured approach aligns with the overall goals of the Fortive Business System, ensuring that the organization continues to deliver extraordinary results and closes the gap between current performance and desired outcomes. If you have specific aspects of the ENSURE sustainment stage you would like to explore further or need assistance with a particular problem, feel free to ask! Would you like to dive deeper into any of these areas? | E14: Neutral | F14: P.Lee Good decent answers, but lacking a few key things. 1) no mention og how the sustaintmaint is going to happen. What is the review cadence of the progress and most important how are they incorporating Daily Management process into the ENSURE SUSTAINMENT step of PSP.
